[2024-09-11T05:24:15.363+0000] {taskinstance.py:1083} INFO - Dependencies all met for <TaskInstance: dbt_init_once_seed_data.load_seed_data_once scheduled__2024-06-01T15:00:00+00:00 [queued]>
[2024-09-11T05:24:15.371+0000] {taskinstance.py:1083} INFO - Dependencies all met for <TaskInstance: dbt_init_once_seed_data.load_seed_data_once scheduled__2024-06-01T15:00:00+00:00 [queued]>
[2024-09-11T05:24:15.371+0000] {taskinstance.py:1279} INFO - 
--------------------------------------------------------------------------------
[2024-09-11T05:24:15.371+0000] {taskinstance.py:1280} INFO - Starting attempt 4 of 4
[2024-09-11T05:24:15.372+0000] {taskinstance.py:1281} INFO - 
--------------------------------------------------------------------------------
[2024-09-11T05:24:15.381+0000] {taskinstance.py:1300} INFO - Executing <Task(BashOperator): load_seed_data_once> on 2024-06-01 15:00:00+00:00
[2024-09-11T05:24:15.384+0000] {standard_task_runner.py:55} INFO - Started process 6030 to run task
[2024-09-11T05:24:15.386+0000] {standard_task_runner.py:82} INFO - Running: ['***', 'tasks', 'run', 'dbt_init_once_seed_data', 'load_seed_data_once', 'scheduled__2024-06-01T15:00:00+00:00', '--job-id', '12', '--raw', '--subdir', 'DAGS_FOLDER/dbt_init.py', '--cfg-path', '/tmp/tmp06u_tjwl']
[2024-09-11T05:24:15.386+0000] {standard_task_runner.py:83} INFO - Job 12: Subtask load_seed_data_once
[2024-09-11T05:24:15.431+0000] {task_command.py:388} INFO - Running <TaskInstance: dbt_init_once_seed_data.load_seed_data_once scheduled__2024-06-01T15:00:00+00:00 [running]> on host 392ef5210b0f
[2024-09-11T05:24:15.492+0000] {taskinstance.py:1507} INFO - Exporting the following env vars:
AIRFLOW_CTX_DAG_OWNER=hyoungwon
AIRFLOW_CTX_DAG_ID=dbt_init_once_seed_data
AIRFLOW_CTX_TASK_ID=load_seed_data_once
AIRFLOW_CTX_EXECUTION_DATE=2024-06-01T15:00:00+00:00
AIRFLOW_CTX_TRY_NUMBER=4
AIRFLOW_CTX_DAG_RUN_ID=scheduled__2024-06-01T15:00:00+00:00
[2024-09-11T05:24:15.493+0000] {subprocess.py:63} INFO - Tmp dir root location: 
 /tmp
[2024-09-11T05:24:15.494+0000] {subprocess.py:75} INFO - Running command: ['/bin/bash', '-c', 'cd /opt/***/dbt && dbt seed --profiles-dir .']
[2024-09-11T05:24:15.503+0000] {subprocess.py:86} INFO - Output:
[2024-09-11T05:24:17.321+0000] {subprocess.py:93} INFO - [0m05:24:17  Running with dbt=1.8.6
[2024-09-11T05:24:17.681+0000] {subprocess.py:93} INFO - [0m05:24:17  Registered adapter: redshift=1.8.1
[2024-09-11T05:24:17.836+0000] {subprocess.py:93} INFO - [0m05:24:17  Unable to do partial parsing because of a version mismatch
[2024-09-11T05:24:19.812+0000] {subprocess.py:93} INFO - [0m05:24:19  Found 9 models, 3 seeds, 486 macros
[2024-09-11T05:24:19.815+0000] {subprocess.py:93} INFO - [0m05:24:19
[2024-09-11T05:24:20.147+0000] {subprocess.py:93} INFO - [0m05:24:20
[2024-09-11T05:24:20.148+0000] {subprocess.py:93} INFO - [0m05:24:20  Finished running  in 0 hours 0 minutes and 0.33 seconds (0.33s).
[2024-09-11T05:24:20.149+0000] {subprocess.py:93} INFO - [0m05:24:20  Encountered an error:
[2024-09-11T05:24:20.149+0000] {subprocess.py:93} INFO - Database Error
[2024-09-11T05:24:20.149+0000] {subprocess.py:93} INFO -   {'S': 'FATAL', 'C': '28000', 'M': 'password authentication failed for user "wnsldjqja"', 'F': '/home/ec2-user/padb/src/pg/src/backend/libpq/auth.c', 'L': '425', 'R': 'auth_failed'}
[2024-09-11T05:24:21.227+0000] {subprocess.py:97} INFO - Command exited with return code 2
[2024-09-11T05:24:21.235+0000] {taskinstance.py:1768} ERROR - Task failed with exception
Traceback (most recent call last):
  File "/home/airflow/.local/lib/python3.8/site-packages/airflow/operators/bash.py", line 196, in execute
    raise AirflowException(
airflow.exceptions.AirflowException: Bash command failed. The command returned a non-zero exit code 2.
[2024-09-11T05:24:21.238+0000] {taskinstance.py:1318} INFO - Marking task as FAILED. dag_id=dbt_init_once_seed_data, task_id=load_seed_data_once, execution_date=20240601T150000, start_date=20240911T052415, end_date=20240911T052421
[2024-09-11T05:24:21.248+0000] {standard_task_runner.py:100} ERROR - Failed to execute job 12 for task load_seed_data_once (Bash command failed. The command returned a non-zero exit code 2.; 6030)
[2024-09-11T05:24:21.290+0000] {local_task_job.py:208} INFO - Task exited with return code 1
[2024-09-11T05:24:21.301+0000] {taskinstance.py:2578} INFO - 0 downstream tasks scheduled from follow-on schedule check
